[32m2024-08-26 13:53:19 -0300[0m - dagster - [34mDEBUG[0m - __ASSET_JOB - 1bffe27f-97f8-486e-9e29-70d458c0c305 - 53364 - LOGS_CAPTURED - Started capturing logs in process (pid: 53364).
[32m2024-08-26 13:53:19 -0300[0m - dagster - [34mDEBUG[0m - __ASSET_JOB - 1bffe27f-97f8-486e-9e29-70d458c0c305 - 53364 - reclamacoes_trusted - STEP_START - Started execution of step "reclamacoes_trusted".
[32m2024-08-26 13:53:19 -0300[0m - dagster - [34mERROR[0m - [31m__ASSET_JOB - 1bffe27f-97f8-486e-9e29-70d458c0c305 - 53364 - reclamacoes_trusted - STEP_FAILURE - Execution of step "reclamacoes_trusted" failed.

dagster._core.errors.DagsterExecutionStepExecutionError: Error occurred while executing op "reclamacoes_trusted"::

ValueError: Unable to parse string " " at position 48

Stack Trace:
  File "/home/roberto/.virtualenvs/dagster/lib/python3.10/site-packages/dagster/_core/execution/plan/utils.py", line 54, in op_execution_error_boundary
    yield
  File "/home/roberto/.virtualenvs/dagster/lib/python3.10/site-packages/dagster/_utils/__init__.py", line 473, in iterate_with_context
    next_output = next(iterator)
  File "/home/roberto/.virtualenvs/dagster/lib/python3.10/site-packages/dagster/_core/execution/plan/compute_generator.py", line 141, in _coerce_op_compute_fn_to_iterator
    result = invoke_compute_fn(
  File "/home/roberto/.virtualenvs/dagster/lib/python3.10/site-packages/dagster/_core/execution/plan/compute_generator.py", line 129, in invoke_compute_fn
    return fn(context, **args_to_pass) if context_arg_provided else fn(**args_to_pass)
  File "/home/roberto/python/pos/ingestao/atividade5_pandas/atividade5/atividade5/assets/reclamacoes.py", line 39, in reclamacoes_trusted
    df_reclamacoes["quantidade_total_de_clientes_ccs_e_scr"] = pd.to_numeric(df_reclamacoes["quantidade_total_de_clientes_ccs_e_scr"])
  File "/home/roberto/.virtualenvs/dagster/lib/python3.10/site-packages/pandas/core/tools/numeric.py", line 232, in to_numeric
    values, new_mask = lib.maybe_convert_numeric(  # type: ignore[call-overload]
  File "lib.pyx", line 2433, in pandas._libs.lib.maybe_convert_numeric

The above exception occurred during handling of the following exception:
ValueError: Unable to parse string " "

Stack Trace:
  File "lib.pyx", line 2391, in pandas._libs.lib.maybe_convert_numeric
[0m
